<?xml version="1.0"?>
<robot xmlns:xacro="http://ros.org/wiki/xacro" name="leobot">

  <xacro:include filename="$(find leobot_description)/robot/robot.urdf.xacro"/>

  <gazebo>
    <plugin name="gazebo_ros_control" filename="libgazebo_ros_control.so">
      <robotNamespace>/leobot</robotNamespace>
      <robotSimType>gazebo_ros_control/DefaultRobotHWSim</robotSimType>
    </plugin>
  </gazebo>

  <gazebo reference="base_link">
    <mu1 value="1.0"/>
    <mu2 value="1.0"/>
    <kp value="10000000.0"/>
    <kd value="1.0"/>
    <material>Gazebo/White</material>
  </gazebo>

  <gazebo reference="left_wheel_link">
    <mu1 value="1.0"/>
    <mu2 value="1.0"/>
    <kp value="10000000.0"/>
    <kd value="1.0"/>
    <material>Gazebo/Red</material>
  </gazebo>

  <gazebo reference="right_wheel_link">
    <mu1 value="1.0"/>
    <mu2 value="1.0"/>
    <kp value="10000000.0"/>
    <kd value="1.0"/>
    <material>Gazebo/Red</material>
  </gazebo>

  <gazebo reference="caster_wheel_link">
    <mu1 value="0.0"/>
    <mu2 value="0.0"/>
    <kp value="10000000.0"/>
    <kd value="1.0"/>
    <material>Gazebo/Red</material>
  </gazebo>

  <gazebo reference="head_link">
    <mu1 value="1.0"/>
    <mu2 value="1.0"/>
    <kp value="10000000.0"/>
    <kd value="1.0"/>
    <material>Gazebo/Red</material>
  </gazebo>

  <link name="head_link">
    <visual>
      <xacro:cylinder_geometry radius="0.15" height="0.1"/>
      <xacro:navajo_white_material/>
    </visual>
    <xacro:cylinder_collision radius="0.15" height="0.1"/>
    <xacro:cylinder_inertia mass="1" radius="0.15" height="0.1"/>
  </link>

  <joint name="head_link_joint" type="revolute">
    <origin rpy="0 0 0" xyz="0 0 0.525"/>
    <axis xyz="0 0 1" />
    <parent link="base_link"/>
    <child link="head_link"/>
    <limit effort="10" velocity="10" lower="${-pi/2}" upper="${pi/2}" />

  </joint>

  <transmission name="head_transmission">
     <type>transmission_interface/SimpleTransmission</type>
     <joint name="head_link_joint">
       <hardwareInterface>hardware_interface/EffortJointInterface</hardwareInterface>
     </joint>
     <actuator name="head_motor">
       <hardwareInterface>EffortJointInterface</hardwareInterface>
       <mechanicalReduction>1</mechanicalReduction>
     </actuator>
  </transmission>

  <gazebo reference="camera_left_link">
    <material>Gazebo/Green</material>
    <sensor type="multicamera" name="stereo_camera">
      <update_rate>30.0</update_rate>
      <camera name="left">
        <horizontal_fov>1.3962634</horizontal_fov>
        <image>
          <width>800</width>
          <height>800</height>
          <format>R8G8B8</format>
        </image>
        <clip>
          <near>0.02</near>
          <far>300</far>
        </clip>
        <noise>
          <type>gaussian</type>
          <mean>0.0</mean>
          <stddev>0.007</stddev>
        </noise>
      </camera>
      <camera name="right">
        <pose>0 -0.07 0 0 0 0</pose>
        <horizontal_fov>1.3962634</horizontal_fov>
        <image>
          <width>800</width>
          <height>800</height>
          <format>R8G8B8</format>
        </image>
        <clip>
          <near>0.02</near>
          <far>300</far>
        </clip>
        <noise>
          <type>gaussian</type>
          <mean>0.0</mean>
          <stddev>0.007</stddev>
        </noise>
      </camera>
      <plugin name="stereo_camera_controller" filename="libgazebo_ros_multicamera.so">
        <alwaysOn>true</alwaysOn>
        <updateRate>0.0</updateRate>
        <cameraName>leobot/stereocamera</cameraName>
        <imageTopicName>image_raw</imageTopicName>
        <cameraInfoTopicName>camera_info</cameraInfoTopicName>
        <frameName>camera_left_link</frameName>
        <rightFrameName>camera_right_link</rightFrameName>
        <hackBaseline>0.07</hackBaseline>
        <distortionK1>0.0</distortionK1>
        <distortionK2>0.0</distortionK2>
        <distortionK3>0.0</distortionK3>
        <distortionT1>0.0</distortionT1>
        <distortionT2>0.0</distortionT2>
      </plugin>
    </sensor>
  </gazebo>

  <gazebo reference="camera_right_link">
    <material>Gazebo/Green</material>
  </gazebo>

</robot>